Workbook
Name Slicer_Category: #N/A
Name Slicer_Region: #N/A
Name Slicer_Segment: #N/A
Name Slicer_Sub_Category: #N/A
Name Slicer_Year: #N/A

Sheet Cover
A1: ═══════════════════════════════════════════
A2: SUPERSTORE SALES ANALYTICS DASHBOARD
A3: Professional Excel Project
A4: ═══════════════════════════════════════════
A6: Created by: Sumit Shinde
A7: Date: January 15, 2026
A8: Project Type: Sales Data Analysis & Visualization
A10: ═══════════════════════════════════════════
A11: DATASET SUMMARY
A12: ═══════════════════════════════════════════
A14: - 9,994 Sales Transactions
A15: - 1,862 Unique Products
... A99: ═══════════════════════════════════════════

Sheet Instructions
A1: HOW TO USE THIS DASHBOARD
A2: ═════════════════════════════════════════
A4: NAVIGATION:
A5: → Go to "Dashboard" tab to see the main dashboard
A7: FILTERING DATA:
A8: → Use the 5 slicers at the top of the dashboard
A9: → Click any item to filter (example: click "Technology")
A10: → All charts and tables update automatically
A11: → Combine multiple filters (example: Technology + West + 2017)
A13: CLEARING FILTERS:
A14: → Click the filter icon (top-right of each slicer)
A15: → Select "Clear Filter"
... A51: → To refresh: Right-click any pivot → Refresh All

Sheet Dashboard
A1: SUPERSTORE SALES DASHBOARD
A2: Interactive Analysis Dashboard - Use Slicers to Filter Data
A15: Total Revenue | F15: TOTAL ORDERS | K15: AVG ORDER VALUE | P15: TOTAL PROFIT
A16: =TEXT(Sales_Analysis!B7,"$#,##0,""K""") -> $2,297K | F16: =TEXT(Sales_Analysis!B8,"#,##0") -> 9,994 | K16: =TEXT(Sales_Analysis!B10,"$#,##0") -> $230 | P16: =TEXT(Sales_Analysis!B12,"$#,##0,""K""") -> $286K
A19: SALES BY CATEGORY
L21: Row Labels | M21: Sum of Sales
L22: Furniture | M22: 741999.8
L23: Office Supplies | M23: 719047.03
L24: Technology | M24: 836154.03
L25: Grand Total | M25: 2297200.9
A39: REGIONAL PERFORMANCE | L39: CUSTOMER SEGMENTS
A60: Row Labels | B60: Sum of Sales | C60: Orders | D60: Sum of Profit | L60: Row Labels | M60: Sum of Sales | N60: Sum of Profit
A61: Central | B61: 501239.89 | C61: 2323 | D61: 39706.362 | L61: Consumer | M61: 1161401.3 | N61: 134119.21
A62: East | B62: 678781.24 | C62: 2848 | D62: 91522.78 | L62: Corporate | M62: 706146.37 | N62: 91979.134
A63: South | B63: 391721.91 | C63: 1620 | D63: 46749.43 | L63: Home Office | M63: 429653.15 | N63: 60298.679
A64: West | B64: 725457.82 | C64: 3203 | D64: 108418.45 | L64: Grand Total | M64: 2297200.9 | N64: 286397.02
A65: Grand Total | B65: 2297200.9 | C65: 9994 | D65: 286397.02
A67: MONTHLY SALES TREND
A88: TOP 10 PRODUCTS BY REVENUE
O90: Row Labels | P90: Sum of Sales
O91: Accessories | P91: 167380.32
O92: Appliances | P92: 107532.16
O93: Binders | P93: 203412.73
O94: Bookcases | P94: 114880
O95: Chairs | P95: 328449.1
O96: Copiers | P96: 149528.03
O97: Machines | P97: 189238.63
O98: Phones | P98: 330007.05
O99: Storage | P99: 223843.61
O100: Tables | P100: 206965.53
O101: Grand Total | P101: 2021237.2

Sheet Sales_Analysis
A1: SALES PERFORMANCE ANALYSIS | M1: QUICK INSIGHTS
A2: Superstore Dataset - Comprehensive Sales Analytics | M2: Top Product Category | N2: =INDEX($A$33:$A$35,MATCH(MAX($B$33:$B$35),$B$33:$B$35,0)) -> Technology
M3: Top Region | N3: =INDEX($G$8:$G$11,MATCH(MAX($H$8:$H$11),$H$8:$H$11,0)) -> West
M4: Top Customer Segment | N4: =INDEX($G$18:$G$20,MATCH(MAX($H$18:$H$20),$H$18:$H$20,0)) -> Consumer
A5: 📊 KEY PERFORMANCE INDICATORS | G5: 🌎 REGIONAL PERFORMANCE | M5: ANALYSIS NOTES
A7: Total Revenue | B7: =SUM(Raw_Data!R:R) -> 2297200.9 | G7: Region | H7: Total Sales (₹) | I7: Orders | J7: Customers | K7: Avg Order | M7: Data Source: Superstore Sales Dataset
A8: Total Orders | B8: =COUNTA(Raw_Data!B:B)-1 -> 9994 | G8: Central | H8: =SUMIF(Raw_Data!$M$2:$M$9995,G8,Raw_Data!$R$2:$R$9995) -> 501239.89 | I8: =COUNTIF(Raw_Data!$M$2:$M$9995,G8) -> 2323 | J8: =COUNTIF(Customer_Master!$F$2:$F$794,G8) -> 184 | K8: =H8/I8 -> 215.77266 | M8: Total Transactions: 9,994
A9: Total Customers | B9: =COUNTA(Customer_Master!A:A)-1 -> 793 | G9: East | H9: =SUMIF(Raw_Data!$M$2:$M$9995,G9,Raw_Data!$R$2:$R$9995) -> 678781.24 | I9: =COUNTIF(Raw_Data!$M$2:$M$9995,G9) -> 2848 | J9: =COUNTIF(Customer_Master!$F$2:$F$794,G9) -> 220 | K9: =H9/I9 -> 238.33611 | M9: Date Range: 2014-2017
A10: Avg Order Value | B10: =B7/B8 -> 229.858 | G10: South | H10: =SUMIF(Raw_Data!$M$2:$M$9995,G10,Raw_Data!$R$2:$R$9995) -> 391721.91 | I10: =COUNTIF(Raw_Data!$M$2:$M$9995,G10) -> 1620 | J10: =COUNTIF(Customer_Master!$F$2:$F$794,G10) -> 134 | K10: =H10/I10 -> 241.80365 | M10: Products Analyzed: 1,862
A11: Total Products Sold | B11: =SUM(Raw_Data!S:S) -> 37873 | G11: West | H11: =SUMIF(Raw_Data!$M$2:$M$9995,G11,Raw_Data!$R$2:$R$9995) -> 725457.82 | I11: =COUNTIF(Raw_Data!$M$2:$M$9995,G11) -> 3203 | J11: =COUNTIF(Customer_Master!$F$2:$F$794,G11) -> 255 | K11: =H11/I11 -> 226.49323 | M11: Customers Analyzed: 793
A12: Total Profit | B12: =SUM(Raw_Data!U:U) -> 286397.02 | G12: Total | H12: =SUM(H8:H11) -> 2297200.9 | I12: =SUM(I8:I11) -> 9994 | J12: =SUM(J8:J11) -> 793 | K12: =SUM(K8:K11) -> 922.40565
A15: 📦 PRODUCT PERFORMANCE | G15: 👥 CUSTOMER SEGMENT ANALYSIS
A17: Product Name | B17: Total Sales (₹) | C17: Units Sold | D17: Avg Price | E17: Profit | G17: Segment | H17: Total Sales (₹) | I17: Orders | J17: Customers | K17: Avg/Customer
A18: =INDEX(Product_Master!$B$2:$B$1863,MATCH(LARGE(Product_Master!$H$2:$H$1863,1),Product_Master!$H$2:$H$1863,0)) -> Canon imageCLASS 2200 Advanced Copier | B18: =LARGE(Product_Master!$H$2:$H$1863,1) -> 61599.824 | C18: =INDEX(Product_Master!$G$2:$G$1863,MATCH(B18,Product_Master!$H$2:$H$1863,0)) -> 20 | D18: =INDEX(Product_Master!$E$2:$E$1863,MATCH(B18,Product_Master!$H$2:$H$1863,0)) -> 12319.965 | E18: =INDEX(Product_Master!$F$2:$F$1863,MATCH(B18,Product_Master!$H$2:$H$1863,0)) -> 5039.9856 | G18: Consumer | H18: =SUMIF(Raw_Data!$H$2:$H$9995,G18,Raw_Data!$R$2:$R$9995) -> 1161401.3 | I18: =COUNTIF(Raw_Data!$H$2:$H$9995,G18) -> 5191 | J18: =COUNTIF(Customer_Master!$C$2:$C$794,G18) -> 409 | K18: =H18/J18 -> 2839.6121
A19: =INDEX(Product_Master!$B$2:$B$1863,MATCH(LARGE(Product_Master!$H$2:$H$1863,2),Product_Master!$H$2:$H$1863,0)) -> Fellowes PB500 Electric Punch Plastic Comb Binding Machine with Manual Bind | B19: =LARGE(Product_Master!$H$2:$H$1863,2) -> 27453.384 | C19: =INDEX(Product_Master!$G$2:$G$1863,MATCH(B19,Product_Master!$H$2:$H$1863,0)) -> 31 | D19: =INDEX(Product_Master!$E$2:$E$1863,MATCH(B19,Product_Master!$H$2:$H$1863,0)) -> 2745.3384 | E19: =INDEX(Product_Master!$F$2:$F$1863,MATCH(B19,Product_Master!$H$2:$H$1863,0)) -> 775.3039 | G19: Corporate | H19: =SUMIF(Raw_Data!$H$2:$H$9995,G19,Raw_Data!$R$2:$R$9995) -> 706146.37 | I19: =COUNTIF(Raw_Data!$H$2:$H$9995,G19) -> 3020 | J19: =COUNTIF(Customer_Master!$C$2:$C$794,G19) -> 236 | K19: =H19/J19 -> 2992.1456
A20: =INDEX(Product_Master!$B$2:$B$1863,MATCH(LARGE(Product_Master!$H$2:$H$1863,3),Product_Master!$H$2:$H$1863,0)) -> Cisco TelePresence System EX90 Videoconferencing Unit | B20: =LARGE(Product_Master!$H$2:$H$1863,3) -> 22638.48 | C20: =INDEX(Product_Master!$G$2:$G$1863,MATCH(B20,Product_Master!$H$2:$H$1863,0)) -> 6 | D20: =INDEX(Product_Master!$E$2:$E$1863,MATCH(B20,Product_Master!$H$2:$H$1863,0)) -> 22638.48 | E20: =INDEX(Product_Master!$F$2:$F$1863,MATCH(B20,Product_Master!$H$2:$H$1863,0)) -> -1811.0784 | G20: home Office | H20: =SUMIF(Raw_Data!$H$2:$H$9995,G20,Raw_Data!$R$2:$R$9995) -> 429653.15 | I20: =COUNTIF(Raw_Data!$H$2:$H$9995,G20) -> 1783 | J20: =COUNTIF(Customer_Master!$C$2:$C$794,G20) -> 148 | K20: =H20/J20 -> 2903.0618
A21: =INDEX(Product_Master!$B$2:$B$1863,MATCH(LARGE(Product_Master!$H$2:$H$1863,4),Product_Master!$H$2:$H$1863,0)) -> HON 5400 Series Task Chairs for Big and Tall | B21: =LARGE(Product_Master!$H$2:$H$1863,4) -> 21870.576 | C21: =INDEX(Product_Master!$G$2:$G$1863,MATCH(B21,Product_Master!$H$2:$H$1863,0)) -> 39 | D21: =INDEX(Product_Master!$E$2:$E$1863,MATCH(B21,Product_Master!$H$2:$H$1863,0)) -> 2733.822 | E21: =INDEX(Product_Master!$F$2:$F$1863,MATCH(B21,Product_Master!$H$2:$H$1863,0)) -> 7.1054274e-15 | G21: Total | H21: =SUM(H18:H20) -> 2297200.9 | I21: =SUM(I18:I20) -> 9994 | J21: =SUM(J18:J20) -> 793 | K21: =SUM(K18:K20) -> 8734.8195
A22: =INDEX(Product_Master!$B$2:$B$1863,MATCH(LARGE(Product_Master!$H$2:$H$1863,5),Product_Master!$H$2:$H$1863,0)) -> GBC DocuBind TL300 Electric Binding System | B22: =LARGE(Product_Master!$H$2:$H$1863,5) -> 19823.479 | C22: =INDEX(Product_Master!$G$2:$G$1863,MATCH(B22,Product_Master!$H$2:$H$1863,0)) -> 37 | D22: =INDEX(Product_Master!$E$2:$E$1863,MATCH(B22,Product_Master!$H$2:$H$1863,0)) -> 1802.1345 | E22: =INDEX(Product_Master!$F$2:$F$1863,MATCH(B22,Product_Master!$H$2:$H$1863,0)) -> 203.04592
A23: =INDEX(Product_Master!$B$2:$B$1863,MATCH(LARGE(Product_Master!$H$2:$H$1863,6),Product_Master!$H$2:$H$1863,0)) -> GBC Ibimaster 500 Manual ProClick Binding System | B23: =LARGE(Product_Master!$H$2:$H$1863,6) -> 19024.5 | C23: =INDEX(Product_Master!$G$2:$G$1863,MATCH(B23,Product_Master!$H$2:$H$1863,0)) -> 48 | D23: =INDEX(Product_Master!$E$2:$E$1863,MATCH(B23,Product_Master!$H$2:$H$1863,0)) -> 2113.8333 | E23: =INDEX(Product_Master!$F$2:$F$1863,MATCH(B23,Product_Master!$H$2:$H$1863,0)) -> 84.553333
A24: =INDEX(Product_Master!$B$2:$B$1863,MATCH(LARGE(Product_Master!$H$2:$H$1863,7),Product_Master!$H$2:$H$1863,0)) -> Hewlett Packard LaserJet 3310 Copier | B24: =LARGE(Product_Master!$H$2:$H$1863,7) -> 18839.686 | C24: =INDEX(Product_Master!$G$2:$G$1863,MATCH(B24,Product_Master!$H$2:$H$1863,0)) -> 38 | D24: =INDEX(Product_Master!$E$2:$E$1863,MATCH(B24,Product_Master!$H$2:$H$1863,0)) -> 2354.9608 | E24: =INDEX(Product_Master!$F$2:$F$1863,MATCH(B24,Product_Master!$H$2:$H$1863,0)) -> 872.98545
A25: =INDEX(Product_Master!$B$2:$B$1863,MATCH(LARGE(Product_Master!$H$2:$H$1863,8),Product_Master!$H$2:$H$1863,0)) -> HP Designjet T520 Inkjet Large Format Printer - 24" Color | B25: =LARGE(Product_Master!$H$2:$H$1863,8) -> 18374.895 | C25: =INDEX(Product_Master!$G$2:$G$1863,MATCH(B25,Product_Master!$H$2:$H$1863,0)) -> 12 | D25: =INDEX(Product_Master!$E$2:$E$1863,MATCH(B25,Product_Master!$H$2:$H$1863,0)) -> 6124.965 | E25: =INDEX(Product_Master!$F$2:$F$1863,MATCH(B25,Product_Master!$H$2:$H$1863,0)) -> 1364.9922
A26: =INDEX(Product_Master!$B$2:$B$1863,MATCH(LARGE(Product_Master!$H$2:$H$1863,9),Product_Master!$H$2:$H$1863,0)) -> GBC DocuBind P400 Electric Binding System | B26: =LARGE(Product_Master!$H$2:$H$1863,9) -> 17965.068 | C26: =INDEX(Product_Master!$G$2:$G$1863,MATCH(B26,Product_Master!$H$2:$H$1863,0)) -> 27 | D26: =INDEX(Product_Master!$E$2:$E$1863,MATCH(B26,Product_Master!$H$2:$H$1863,0)) -> 2994.178 | E26: =INDEX(Product_Master!$F$2:$F$1863,MATCH(B26,Product_Master!$H$2:$H$1863,0)) -> -313.0277
A27: =INDEX(Product_Master!$B$2:$B$1863,MATCH(LARGE(Product_Master!$H$2:$H$1863,10),Product_Master!$H$2:$H$1863,0)) -> High Speed Automatic Electric Letter Opener | B27: =LARGE(Product_Master!$H$2:$H$1863,10) -> 17030.312 | C27: =INDEX(Product_Master!$G$2:$G$1863,MATCH(B27,Product_Master!$H$2:$H$1863,0)) -> 11 | D27: =INDEX(Product_Master!$E$2:$E$1863,MATCH(B27,Product_Master!$H$2:$H$1863,0)) -> 5676.7707 | E27: =INDEX(Product_Master!$F$2:$F$1863,MATCH(B27,Product_Master!$H$2:$H$1863,0)) -> -87.334933
A30: 📂 CATEGORY BREAKDOWN
A32: Category | B32: Total Sales (₹) | C32: Units Sold | D32: Orders | E32: Avg Sales
A33: Furniture | B33: =SUMIF(Raw_Data!$O$2:$O$9995,A33,Raw_Data!$R$2:$R$9995) -> 741999.8 | C33: =SUMIF(Raw_Data!$O$2:$O$9995,A33,Raw_Data!$S$2:$S$9995) -> 8028 | D33: =COUNTIF(Raw_Data!$O$2:$O$9995,A33) -> 2121 | E33: =B33/D33 -> 349.83489
A34: Office Supplies | B34: =SUMIF(Raw_Data!$O$2:$O$9995,A34,Raw_Data!$R$2:$R$9995) -> 719047.03 | C34: =SUMIF(Raw_Data!$O$2:$O$9995,A34,Raw_Data!$S$2:$S$9995) -> 22906 | D34: =COUNTIF(Raw_Data!$O$2:$O$9995,A34) -> 6026 | E34: =B34/D34 -> 119.3241
A35: Technology | B35: =SUMIF(Raw_Data!$O$2:$O$9995,A35,Raw_Data!$R$2:$R$9995) -> 836154.03 | C35: =SUMIF(Raw_Data!$O$2:$O$9995,A35,Raw_Data!$S$2:$S$9995) -> 6939 | D35: =COUNTIF(Raw_Data!$O$2:$O$9995,A35) -> 1847 | E35: =B35/D35 -> 452.70928
A36: Total | B36: =SUM(B33:B35) -> 2297200.9 | C36: =SUM(C33:C35) -> 37873 | D36: =SUM(D33:D35) -> 9994 | E36: =SUM(E33:E35) -> 921.86826
A40: 📅 TIME-BASED ANALYSIS
A42: Month (2017) | B42: Total Sales (₹) | C42: Orders | D42: Avg Order | E42: Growth %
A43: Jan | B43: =SUMIFS(Raw_Data!$R$2:$R$9995,Raw_Data!$X$2:$X$9995,2017,Raw_Data!$Y$2:$Y$9995,"Jan") -> 43971.374 | C43: =COUNTIFS(Raw_Data!$X$2:$X$9995,2017,Raw_Data!$Y$2:$Y$9995,"Jan") -> 155 | D43: =B43/C43 -> 283.68628
A44: Feb | B44: =SUMIFS(Raw_Data!$R$2:$R$9995,Raw_Data!$X$2:$X$9995,2017,Raw_Data!$Y$2:$Y$9995,"Feb") -> 20301.133 | C44: =COUNTIFS(Raw_Data!$X$2:$X$9995,2017,Raw_Data!$Y$2:$Y$9995,"Feb") -> 107 | D44: =B44/C44 -> 189.73022 | E44: =IF(B43>0,(B44-B43)/B43*100,"") -> -53.831023
A45: Mar | B45: =SUMIFS(Raw_Data!$R$2:$R$9995,Raw_Data!$X$2:$X$9995,2017,Raw_Data!$Y$2:$Y$9995,"Mar") -> 58872.353 | C45: =COUNTIFS(Raw_Data!$X$2:$X$9995,2017,Raw_Data!$Y$2:$Y$9995,"Mar") -> 238 | D45: =B45/C45 -> 247.36283 | E45: =IF(B44>0,(B45-B44)/B44*100,"") -> 189.9954
A46: Apr | B46: =SUMIFS(Raw_Data!$R$2:$R$9995,Raw_Data!$X$2:$X$9995,2017,Raw_Data!$Y$2:$Y$9995,"Apr") -> 36521.536 | C46: =COUNTIFS(Raw_Data!$X$2:$X$9995,2017,Raw_Data!$Y$2:$Y$9995,"Apr") -> 203 | D46: =B46/C46 -> 179.90904 | E46: =IF(B45>0,(B46-B45)/B45*100,"") -> -37.964878
A47: May | B47: =SUMIFS(Raw_Data!$R$2:$R$9995,Raw_Data!$X$2:$X$9995,2017,Raw_Data!$Y$2:$Y$9995,"May") -> 44261.11 | C47: =COUNTIFS(Raw_Data!$X$2:$X$9995,2017,Raw_Data!$Y$2:$Y$9995,"May") -> 242 | D47: =B47/C47 -> 182.89715 | E47: =IF(B46>0,(B47-B46)/B46*100,"") -> 21.191809
A48: Jun | B48: =SUMIFS(Raw_Data!$R$2:$R$9995,Raw_Data!$X$2:$X$9995,2017,Raw_Data!$Y$2:$Y$9995,"Jun") -> 52981.726 | C48: =COUNTIFS(Raw_Data!$X$2:$X$9995,2017,Raw_Data!$Y$2:$Y$9995,"Jun") -> 245 | D48: =B48/C48 -> 216.25194 | E48: =IF(B47>0,(B48-B47)/B47*100,"") -> 19.702659
A49: Jul | B49: =SUMIFS(Raw_Data!$R$2:$R$9995,Raw_Data!$X$2:$X$9995,2017,Raw_Data!$Y$2:$Y$9995,"Jul") -> 45264.416 | C49: =COUNTIFS(Raw_Data!$X$2:$X$9995,2017,Raw_Data!$Y$2:$Y$9995,"Jul") -> 226 | D49: =B49/C49 -> 200.28503 | E49: =IF(B48>0,(B49-B48)/B48*100,"") -> -14.565984
A50: Aug | B50: =SUMIFS(Raw_Data!$R$2:$R$9995,Raw_Data!$X$2:$X$9995,2017,Raw_Data!$Y$2:$Y$9995,"Aug") -> 63120.888 | C50: =COUNTIFS(Raw_Data!$X$2:$X$9995,2017,Raw_Data!$Y$2:$Y$9995,"Aug") -> 218 | D50: =B50/C50 -> 289.54536 | E50: =IF(B49>0,(B50-B49)/B49*100,"") -> 39.449249
A51: Sep | B51: =SUMIFS(Raw_Data!$R$2:$R$9995,Raw_Data!$X$2:$X$9995,2017,Raw_Data!$Y$2:$Y$9995,"Sep") -> 87866.652 | C51: =COUNTIFS(Raw_Data!$X$2:$X$9995,2017,Raw_Data!$Y$2:$Y$9995,"Sep") -> 459 | D51: =B51/C51 -> 191.43061 | E51: =IF(B50>0,(B51-B50)/B50*100,"") -> 39.203764
...

Sheet Customer_Master
A1: Customer ID | B1: Customer Name | C1: Segment | D1: City | E1: State | F1: Region | G1: Total Purchases | H1: Total Spent | I1: Avg Order Value | J1: Customer Tier
A2: CG-12520 | B2: =IFERROR(INDEX(Raw_Data!G:G,MATCH(Customer_Master!A2,Raw_Data!F:F,0)),"Not found") -> Claire Gute | C2: =INDEX(Raw_Data!H:H,MATCH(Customer_Master!A2,Raw_Data!F:F,0)) -> Consumer | D2: =INDEX(Raw_Data!J:J,MATCH(Customer_Master!A2,Raw_Data!F:F,0)) -> Henderson | E2: =INDEX(Raw_Data!J:J,MATCH(Customer_Master!A2,Raw_Data!F:F,0)) -> Henderson | F2: =INDEX(Raw_Data!M:M,MATCH(Customer_Master!A2,Raw_Data!F:F,0)) -> South | G2: =COUNTIF(Raw_Data!F:F,Customer_Master!A2) -> 5 | H2: =SUMIF(Raw_Data!F:F,Customer_Master!A2,Raw_Data!R:R) -> 1148.78 | I2: =H2/G2 -> 229.756 | J2: =IF(H2>5000,"VIP",IF(H2>2000,"Gold","Silver")) -> Silver
A3: DV-13045 | B3: =IFERROR(INDEX(Raw_Data!G:G,MATCH(Customer_Master!A3,Raw_Data!F:F,0)),"Not found") -> Darrin Van Huff | C3: =INDEX(Raw_Data!H:H,MATCH(Customer_Master!A3,Raw_Data!F:F,0)) -> Corporate | D3: =INDEX(Raw_Data!J:J,MATCH(Customer_Master!A3,Raw_Data!F:F,0)) -> Los Angeles | E3: =INDEX(Raw_Data!J:J,MATCH(Customer_Master!A3,Raw_Data!F:F,0)) -> Los Angeles | F3: =INDEX(Raw_Data!M:M,MATCH(Customer_Master!A3,Raw_Data!F:F,0)) -> West | G3: =COUNTIF(Raw_Data!F:F,Customer_Master!A3) -> 9 | H3: =SUMIF(Raw_Data!F:F,Customer_Master!A3,Raw_Data!R:R) -> 1119.483 | I3: =H3/G3 -> 124.387 | J3: =IF(H3>5000,"VIP",IF(H3>2000,"Gold","Silver")) -> Silver | L3: Max Spent | M3: =MAX(H:H) -> 25043.05
A4: SO-20335 | B4: =IFERROR(INDEX(Raw_Data!G:G,MATCH(Customer_Master!A4,Raw_Data!F:F,0)),"Not found") -> Sean O'Donnell | C4: =INDEX(Raw_Data!H:H,MATCH(Customer_Master!A4,Raw_Data!F:F,0)) -> Consumer | D4: =INDEX(Raw_Data!J:J,MATCH(Customer_Master!A4,Raw_Data!F:F,0)) -> Fort Lauderdale | E4: =INDEX(Raw_Data!J:J,MATCH(Customer_Master!A4,Raw_Data!F:F,0)) -> Fort Lauderdale | F4: =INDEX(Raw_Data!M:M,MATCH(Customer_Master!A4,Raw_Data!F:F,0)) -> South | G4: =COUNTIF(Raw_Data!F:F,Customer_Master!A4) -> 15 | H4: =SUMIF(Raw_Data!F:F,Customer_Master!A4,Raw_Data!R:R) -> 2602.5755 | I4: =H4/G4 -> 173.50503 | J4: =IF(H4>5000,"VIP",IF(H4>2000,"Gold","Silver")) -> Gold | L4: Min Spent | M4: =MIN(H:H) -> 4.833
A5: BH-11710 | B5: =IFERROR(INDEX(Raw_Data!G:G,MATCH(Customer_Master!A5,Raw_Data!F:F,0)),"Not found") -> Brosina Hoffman | C5: =INDEX(Raw_Data!H:H,MATCH(Customer_Master!A5,Raw_Data!F:F,0)) -> Consumer | D5: =INDEX(Raw_Data!J:J,MATCH(Customer_Master!A5,Raw_Data!F:F,0)) -> Los Angeles | E5: =INDEX(Raw_Data!J:J,MATCH(Customer_Master!A5,Raw_Data!F:F,0)) -> Los Angeles | F5: =INDEX(Raw_Data!M:M,MATCH(Customer_Master!A5,Raw_Data!F:F,0)) -> West | G5: =COUNTIF(Raw_Data!F:F,Customer_Master!A5) -> 24 | H5: =SUMIF(Raw_Data!F:F,Customer_Master!A5,Raw_Data!R:R) -> 6255.351 | I5: =H5/G5 -> 260.63963 | J5: =IF(H5>5000,"VIP",IF(H5>2000,"Gold","Silver")) -> VIP | L5: Average Spent | M5: =AVERAGE(H:H) -> 2896.8485
A6: AA-10480 | B6: =IFERROR(INDEX(Raw_Data!G:G,MATCH(Customer_Master!A6,Raw_Data!F:F,0)),"Not found") -> Andrew Allen | C6: =INDEX(Raw_Data!H:H,MATCH(Customer_Master!A6,Raw_Data!F:F,0)) -> Consumer | D6: =INDEX(Raw_Data!J:J,MATCH(Customer_Master!A6,Raw_Data!F:F,0)) -> Concord | E6: =INDEX(Raw_Data!J:J,MATCH(Customer_Master!A6,Raw_Data!F:F,0)) -> Concord | F6: =INDEX(Raw_Data!M:M,MATCH(Customer_Master!A6,Raw_Data!F:F,0)) -> South | G6: =COUNTIF(Raw_Data!F:F,Customer_Master!A6) -> 12 | H6: =SUMIF(Raw_Data!F:F,Customer_Master!A6,Raw_Data!R:R) -> 1790.512 | I6: =H6/G6 -> 149.20933 | J6: =IF(H6>5000,"VIP",IF(H6>2000,"Gold","Silver")) -> Silver | L6: Median Spent | M6: =MEDIAN(H:H) -> 2256.394
A7: IM-15070 | B7: =IFERROR(INDEX(Raw_Data!G:G,MATCH(Customer_Master!A7,Raw_Data!F:F,0)),"Not found") -> Irene Maddox | C7: =INDEX(Raw_Data!H:H,MATCH(Customer_Master!A7,Raw_Data!F:F,0)) -> Consumer | D7: =INDEX(Raw_Data!J:J,MATCH(Customer_Master!A7,Raw_Data!F:F,0)) -> Seattle | E7: =INDEX(Raw_Data!J:J,MATCH(Customer_Master!A7,Raw_Data!F:F,0)) -> Seattle | F7: =INDEX(Raw_Data!M:M,MATCH(Customer_Master!A7,Raw_Data!F:F,0)) -> West | G7: =COUNTIF(Raw_Data!F:F,Customer_Master!A7) -> 21 | H7: =SUMIF(Raw_Data!F:F,Customer_Master!A7,Raw_Data!R:R) -> 4930.474 | I7: =H7/G7 -> 234.78448 | J7: =IF(H7>5000,"VIP",IF(H7>2000,"Gold","Silver")) -> Gold
A8: HP-14815 | B8: =IFERROR(INDEX(Raw_Data!G:G,MATCH(Customer_Master!A8,Raw_Data!F:F,0)),"Not found") -> Harold Pawlan | C8: =INDEX(Raw_Data!H:H,MATCH(Customer_Master!A8,Raw_Data!F:F,0)) -> Home Office | D8: =INDEX(Raw_Data!J:J,MATCH(Customer_Master!A8,Raw_Data!F:F,0)) -> Fort Worth | E8: =INDEX(Raw_Data!J:J,MATCH(Customer_Master!A8,Raw_Data!F:F,0)) -> Fort Worth | F8: =INDEX(Raw_Data!M:M,MATCH(Customer_Master!A8,Raw_Data!F:F,0)) -> Central | G8: =COUNTIF(Raw_Data!F:F,Customer_Master!A8) -> 10 | H8: =SUMIF(Raw_Data!F:F,Customer_Master!A8,Raw_Data!R:R) -> 1990.314 | I8: =H8/G8 -> 199.0314 | J8: =IF(H8>5000,"VIP",IF(H8>2000,"Gold","Silver")) -> Silver | L8: VIP Count | M8: =COUNTIF(J:J,"VIP") -> 117
A9: PK-19075 | B9: =IFERROR(INDEX(Raw_Data!G:G,MATCH(Customer_Master!A9,Raw_Data!F:F,0)),"Not found") -> Pete Kriz | C9: =INDEX(Raw_Data!H:H,MATCH(Customer_Master!A9,Raw_Data!F:F,0)) -> Consumer | D9: =INDEX(Raw_Data!J:J,MATCH(Customer_Master!A9,Raw_Data!F:F,0)) -> Madison | E9: =INDEX(Raw_Data!J:J,MATCH(Customer_Master!A9,Raw_Data!F:F,0)) -> Madison | F9: =INDEX(Raw_Data!M:M,MATCH(Customer_Master!A9,Raw_Data!F:F,0)) -> Central | G9: =COUNTIF(Raw_Data!F:F,Customer_Master!A9) -> 25 | H9: =SUMIF(Raw_Data!F:F,Customer_Master!A9,Raw_Data!R:R) -> 8646.934 | I9: =H9/G9 -> 345.87736 | J9: =IF(H9>5000,"VIP",IF(H9>2000,"Gold","Silver")) -> VIP | L9: Gold Count | M9: =COUNTIF(J:J,"Gold") -> 323
A10: AG-10270 | B10: =IFERROR(INDEX(Raw_Data!G:G,MATCH(Customer_Master!A10,Raw_Data!F:F,0)),"Not found") -> Alejandro Grove | C10: =INDEX(Raw_Data!H:H,MATCH(Customer_Master!A10,Raw_Data!F:F,0)) -> Consumer | D10: =INDEX(Raw_Data!J:J,MATCH(Customer_Master!A10,Raw_Data!F:F,0)) -> West Jordan | E10: =INDEX(Raw_Data!J:J,MATCH(Customer_Master!A10,Raw_Data!F:F,0)) -> West Jordan | F10: =INDEX(Raw_Data!M:M,MATCH(Customer_Master!A10,Raw_Data!F:F,0)) -> West | G10: =COUNTIF(Raw_Data!F:F,Customer_Master!A10) -> 14 | H10: =SUMIF(Raw_Data!F:F,Customer_Master!A10,Raw_Data!R:R) -> 2582.898 | I10: =H10/G10 -> 184.49271 | J10: =IF(H10>5000,"VIP",IF(H10>2000,"Gold","Silver")) -> Gold | L10: Silver Count | M10: =COUNTIF(J:J,"Silver") -> 353
A11: ZD-21925 | B11: =IFERROR(INDEX(Raw_Data!G:G,MATCH(Customer_Master!A11,Raw_Data!F:F,0)),"Not found") -> Zuschuss Donatelli | C11: =INDEX(Raw_Data!H:H,MATCH(Customer_Master!A11,Raw_Data!F:F,0)) -> Consumer | D11: =INDEX(Raw_Data!J:J,MATCH(Customer_Master!A11,Raw_Data!F:F,0)) -> San Francisco | E11: =INDEX(Raw_Data!J:J,MATCH(Customer_Master!A11,Raw_Data!F:F,0)) -> San Francisco | F11: =INDEX(Raw_Data!M:M,MATCH(Customer_Master!A11,Raw_Data!F:F,0)) -> West | G11: =COUNTIF(Raw_Data!F:F,Customer_Master!A11) -> 9 | H11: =SUMIF(Raw_Data!F:F,Customer_Master!A11,Raw_Data!R:R) -> 1493.944 | I11: =H11/G11 -> 165.99378 | J11: =IF(H11>5000,"VIP",IF(H11>2000,"Gold","Silver")) -> Silver | L11: Total Coustomers | M11: =SUM(M8:M10) -> 793
A12: KB-16585 | B12: =IFERROR(INDEX(Raw_Data!G:G,MATCH(Customer_Master!A12,Raw_Data!F:F,0)),"Not found") -> Ken Black | C12: =INDEX(Raw_Data!H:H,MATCH(Customer_Master!A12,Raw_Data!F:F,0)) -> Corporate | D12: =INDEX(Raw_Data!J:J,MATCH(Customer_Master!A12,Raw_Data!F:F,0)) -> Fremont | E12: =INDEX(Raw_Data!J:J,MATCH(Customer_Master!A12,Raw_Data!F:F,0)) -> Fremont | F12: =INDEX(Raw_Data!M:M,MATCH(Customer_Master!A12,Raw_Data!F:F,0)) -> Central | G12: =COUNTIF(Raw_Data!F:F,Customer_Master!A12) -> 23 | H12: =SUMIF(Raw_Data!F:F,Customer_Master!A12,Raw_Data!R:R) -> 2744.742 | I12: =H12/G12 -> 119.33661 | J12: =IF(H12>5000,"VIP",IF(H12>2000,"Gold","Silver")) -> Gold
A13: SF-20065 | B13: =IFERROR(INDEX(Raw_Data!G:G,MATCH(Customer_Master!A13,Raw_Data!F:F,0)),"Not found") -> Sandra Flanagan | C13: =INDEX(Raw_Data!H:H,MATCH(Customer_Master!A13,Raw_Data!F:F,0)) -> Consumer | D13: =INDEX(Raw_Data!J:J,MATCH(Customer_Master!A13,Raw_Data!F:F,0)) -> Philadelphia | E13: =INDEX(Raw_Data!J:J,MATCH(Customer_Master!A13,Raw_Data!F:F,0)) -> Philadelphia | F13: =INDEX(Raw_Data!M:M,MATCH(Customer_Master!A13,Raw_Data!F:F,0)) -> East | G13: =COUNTIF(Raw_Data!F:F,Customer_Master!A13) -> 9 | H13: =SUMIF(Raw_Data!F:F,Customer_Master!A13,Raw_Data!R:R) -> 763.546 | I13: =H13/G13 -> 84.838444 | J13: =IF(H13>5000,"VIP",IF(H13>2000,"Gold","Silver")) -> Silver
A14: EB-13870 | B14: =IFERROR(INDEX(Raw_Data!G:G,MATCH(Customer_Master!A14,Raw_Data!F:F,0)),"Not found") -> Emily Burns | C14: =INDEX(Raw_Data!H:H,MATCH(Customer_Master!A14,Raw_Data!F:F,0)) -> Consumer | D14: =INDEX(Raw_Data!J:J,MATCH(Customer_Master!A14,Raw_Data!F:F,0)) -> Orem | E14: =INDEX(Raw_Data!J:J,MATCH(Customer_Master!A14,Raw_Data!F:F,0)) -> Orem | F14: =INDEX(Raw_Data!M:M,MATCH(Customer_Master!A14,Raw_Data!F:F,0)) -> West | G14: =COUNTIF(Raw_Data!F:F,Customer_Master!A14) -> 11 | H14: =SUMIF(Raw_Data!F:F,Customer_Master!A14,Raw_Data!R:R) -> 2767.219 | I14: =H14/G14 -> 251.56536 | J14: =IF(H14>5000,"VIP",IF(H14>2000,"Gold","Silver")) -> Gold
A15: EH-13945 | B15: =IFERROR(INDEX(Raw_Data!G:G,MATCH(Customer_Master!A15,Raw_Data!F:F,0)),"Not found") -> Eric Hoffmann | C15: =INDEX(Raw_Data!H:H,MATCH(Customer_Master!A15,Raw_Data!F:F,0)) -> Consumer | D15: =INDEX(Raw_Data!J:J,MATCH(Customer_Master!A15,Raw_Data!F:F,0)) -> Los Angeles | E15: =INDEX(Raw_Data!J:J,MATCH(Customer_Master!A15,Raw_Data!F:F,0)) -> Los Angeles | F15: =INDEX(Raw_Data!M:M,MATCH(Customer_Master!A15,Raw_Data!F:F,0)) -> West | G15: =COUNTIF(Raw_Data!F:F,Customer_Master!A15) -> 17 | H15: =SUMIF(Raw_Data!F:F,Customer_Master!A15,Raw_Data!R:R) -> 684.171 | I15: =H15/G15 -> 40.245353 | J15: =IF(H15>5000,"VIP",IF(H15>2000,"Gold","Silver")) -> Silver
A16: TB-21520 | B16: =IFERROR(INDEX(Raw_Data!G:G,MATCH(Customer_Master!A16,Raw_Data!F:F,0)),"Not found") -> Tracy Blumstein | C16: =INDEX(Raw_Data!H:H,MATCH(Customer_Master!A16,Raw_Data!F:F,0)) -> Consumer | D16: =INDEX(Raw_Data!J:J,MATCH(Customer_Master!A16,Raw_Data!F:F,0)) -> Philadelphia | E16: =INDEX(Raw_Data!J:J,MATCH(Customer_Master!A16,Raw_Data!F:F,0)) -> Philadelphia | F16: =INDEX(Raw_Data!M:M,MATCH(Customer_Master!A16,Raw_Data!F:F,0)) -> East | G16: =COUNTIF(Raw_Data!F:F,Customer_Master!A16) -> 20 | H16: =SUMIF(Raw_Data!F:F,Customer_Master!A16,Raw_Data!R:R) -> 4737.486 | I16: =H16/G16 -> 236.8743 | J16: =IF(H16>5000,"VIP",IF(H16>2000,"Gold","Silver")) -> Gold
A17: MA-17560 | B17: =IFERROR(INDEX(Raw_Data!G:G,MATCH(Customer_Master!A17,Raw_Data!F:F,0)),"Not found") -> Matt Abelman | C17: =INDEX(Raw_Data!H:H,MATCH(Customer_Master!A17,Raw_Data!F:F,0)) -> Home Office | D17: =INDEX(Raw_Data!J:J,MATCH(Customer_Master!A17,Raw_Data!F:F,0)) -> Houston | E17: =INDEX(Raw_Data!J:J,MATCH(Customer_Master!A17,Raw_Data!F:F,0)) -> Houston | F17: =INDEX(Raw_Data!M:M,MATCH(Customer_Master!A17,Raw_Data!F:F,0)) -> Central | G17: =COUNTIF(Raw_Data!F:F,Customer_Master!A17) -> 34 | H17: =SUMIF(Raw_Data!F:F,Customer_Master!A17,Raw_Data!R:R) -> 4299.161 | I17: =H17/G17 -> 126.44591 | J17: =IF(H17>5000,"VIP",IF(H17>2000,"Gold","Silver")) -> Gold
A18: GH-14485 | B18: =IFERROR(INDEX(Raw_Data!G:G,MATCH(Customer_Master!A18,Raw_Data!F:F,0)),"Not found") -> Gene Hale | C18: =INDEX(Raw_Data!H:H,MATCH(Customer_Master!A18,Raw_Data!F:F,0)) -> Corporate | D18: =INDEX(Raw_Data!J:J,MATCH(Customer_Master!A18,Raw_Data!F:F,0)) -> Richardson | E18: =INDEX(Raw_Data!J:J,MATCH(Customer_Master!A18,Raw_Data!F:F,0)) -> Richardson | F18: =INDEX(Raw_Data!M:M,MATCH(Customer_Master!A18,Raw_Data!F:F,0)) -> Central | G18: =COUNTIF(Raw_Data!F:F,Customer_Master!A18) -> 3 | H18: =SUMIF(Raw_Data!F:F,Customer_Master!A18,Raw_Data!R:R) -> 1361.244 | I18: =H18/G18 -> 453.748 | J18: =IF(H18>5000,"VIP",IF(H18>2000,"Gold","Silver")) -> Silver
A19: SN-20710 | B19: =IFERROR(INDEX(Raw_Data!G:G,MATCH(Customer_Master!A19,Raw_Data!F:F,0)),"Not found") -> Steve Nguyen | C19: =INDEX(Raw_Data!H:H,MATCH(Customer_Master!A19,Raw_Data!F:F,0)) -> Home Office | D19: =INDEX(Raw_Data!J:J,MATCH(Customer_Master!A19,Raw_Data!F:F,0)) -> Houston | E19: =INDEX(Raw_Data!J:J,MATCH(Customer_Master!A19,Raw_Data!F:F,0)) -> Houston | F19: =INDEX(Raw_Data!M:M,MATCH(Customer_Master!A19,Raw_Data!F:F,0)) -> Central | G19: =COUNTIF(Raw_Data!F:F,Customer_Master!A19) -> 19 | H19: =SUMIF(Raw_Data!F:F,Customer_Master!A19,Raw_Data!R:R) -> 3127.9592 | I19: =H19/G19 -> 164.62943 | J19: =IF(H19>5000,"VIP",IF(H19>2000,"Gold","Silver")) -> Gold
A20: LC-16930 | B20: =IFERROR(INDEX(Raw_Data!G:G,MATCH(Customer_Master!A20,Raw_Data!F:F,0)),"Not found") -> Linda Cazamias | C20: =INDEX(Raw_Data!H:H,MATCH(Customer_Master!A20,Raw_Data!F:F,0)) -> Corporate | D20: =INDEX(Raw_Data!J:J,MATCH(Customer_Master!A20,Raw_Data!F:F,0)) -> Naperville | E20: =INDEX(Raw_Data!J:J,MATCH(Customer_Master!A20,Raw_Data!F:F,0)) -> Naperville | F20: =INDEX(Raw_Data!M:M,MATCH(Customer_Master!A20,Raw_Data!F:F,0)) -> Central | G20: =COUNTIF(Raw_Data!F:F,Customer_Master!A20) -> 14 | H20: =SUMIF(Raw_Data!F:F,Customer_Master!A20,Raw_Data!R:R) -> 4492.946 | I20: =H20/G20 -> 320.92471 | J20: =IF(H20>5000,"VIP",IF(H20>2000,"Gold","Silver")) -> Gold
A21: RA-19885 | B21: =IFERROR(INDEX(Raw_Data!G:G,MATCH(Customer_Master!A21,Raw_Data!F:F,0)),"Not found") -> Ruben Ausman | C21: =INDEX(Raw_Data!H:H,MATCH(Customer_Master!A21,Raw_Data!F:F,0)) -> Corporate | D21: =INDEX(Raw_Data!J:J,MATCH(Customer_Master!A21,Raw_Data!F:F,0)) -> Los Angeles | E21: =INDEX(Raw_Data!J:J,MATCH(Customer_Master!A21,Raw_Data!F:F,0)) -> Los Angeles | F21: =INDEX(Raw_Data!M:M,MATCH(Customer_Master!A21,Raw_Data!F:F,0)) -> West | G21: =COUNTIF(Raw_Data!F:F,Customer_Master!A21) -> 15 | H21: =SUMIF(Raw_Data!F:F,Customer_Master!A21,Raw_Data!R:R) -> 3832.314 | I21: =H21/G21 -> 255.4876 | J21: =IF(H21>5000,"VIP",IF(H21>2000,"Gold","Silver")) -> Gold
A22: ES-14080 | B22: =IFERROR(INDEX(Raw_Data!G:G,MATCH(Customer_Master!A22,Raw_Data!F:F,0)),"Not found") -> Erin Smith | C22: =INDEX(Raw_Data!H:H,MATCH(Customer_Master!A22,Raw_Data!F:F,0)) -> Corporate | D22: =INDEX(Raw_Data!J:J,MATCH(Customer_Master!A22,Raw_Data!F:F,0)) -> Melbourne | E22: =INDEX(Raw_Data!J:J,MATCH(Customer_Master!A22,Raw_Data!F:F,0)) -> Melbourne | F22: =INDEX(Raw_Data!M:M,MATCH(Customer_Master!A22,Raw_Data!F:F,0)) -> South | G22: =COUNTIF(Raw_Data!F:F,Customer_Master!A22) -> 20 | H22: =SUMIF(Raw_Data!F:F,Customer_Master!A22,Raw_Data!R:R) -> 4657.924 | I22: =H22/G22 -> 232.8962 | J22: =IF(H22>5000,"VIP",IF(H22>2000,"Gold","Silver")) -> Gold
A23: ON-18715 | B23: =IFERROR(INDEX(Raw_Data!G:G,MATCH(Customer_Master!A23,Raw_Data!F:F,0)),"Not found") -> Odella Nelson | C23: =INDEX(Raw_Data!H:H,MATCH(Customer_Master!A23,Raw_Data!F:F,0)) -> Corporate | D23: =INDEX(Raw_Data!J:J,MATCH(Customer_Master!A23,Raw_Data!F:F,0)) -> Eagan | E23: =INDEX(Raw_Data!J:J,MATCH(Customer_Master!A23,Raw_Data!F:F,0)) -> Eagan | F23: =INDEX(Raw_Data!M:M,MATCH(Customer_Master!A23,Raw_Data!F:F,0)) -> Central | G23: =COUNTIF(Raw_Data!F:F,Customer_Master!A23) -> 15 | H23: =SUMIF(Raw_Data!F:F,Customer_Master!A23,Raw_Data!R:R) -> 1567.52 | I23: =H23/G23 -> 104.50133 | J23: =IF(H23>5000,"VIP",IF(H23>2000,"Gold","Silver")) -> Silver
... A794: SM-20905 | B794: =IFERROR(INDEX(Raw_Data!G:G,MATCH(Customer_Master!A794,Raw_Data!F:F,0)),"Not found") -> Susan MacKendrick | C794: =INDEX(Raw_Data!H:H,MATCH(Customer_Master!A794,Raw_Data!F:F,0)) -> Consumer | D794: =INDEX(Raw_Data!J:J,MATCH(Customer_Master!A794,Raw_Data!F:F,0)) -> Newark | E794: =INDEX(Raw_Data!J:J,MATCH(Customer_Master!A794,Raw_Data!F:F,0)) -> Newark | F794: =INDEX(Raw_Data!M:M,MATCH(Customer_Master!A794,Raw_Data!F:F,0)) -> East | G794: =COUNTIF(Raw_Data!F:F,Customer_Master!A794) -> 6 | H794: =SUMIF(Raw_Data!F:F,Customer_Master!A794,Raw_Data!R:R) -> 1043.041 | I794: =H794/G794 -> 173.84017 | J794: =IF(H794>5000,"VIP",IF(H794>2000,"Gold","Silver")) -> Silver

Sheet Product_Master
A1: Product ID | B1: Product Name | C1: Category | D1: Sub-Category | E1: Avg Sales Price | F1: Avg Profit | G1: Total Units Sold | H1: Total Revenue | I1: Profit Margin% | J1: Status | L1: Revenue Analysis
A2: FUR-BO-10001798 | B2: =IFERROR(INDEX(Raw_Data!Q:Q,MATCH(Product_Master!A2,Raw_Data!N:N,0)),"NOT FOUND") -> Bush Somerset Collection Bookcase | C2: =IFERROR(INDEX(Raw_Data!O:O,MATCH(Product_Master!A2,Raw_Data!N:N,0)),"NOT FOUND") -> Furniture | D2: =IFERROR(INDEX(Raw_Data!P:P,MATCH(Product_Master!A2,Raw_Data!N:N,0)),"NOT FOUND") -> Bookcases | E2: =AVERAGEIF(Raw_Data!N:N,Product_Master!A2,Raw_Data!R:R) -> 315.98925 | F2: =AVERAGEIF(Raw_Data!N:N,Product_Master!A2,Raw_Data!U:U) -> -14.08035 | G2: =SUMIF(Raw_Data!N:N,Product_Master!A2,Raw_Data!S:S) -> 12 | H2: =SUMIF(Raw_Data!N:N,Product_Master!A2,Raw_Data!R:R) -> 1263.957 | I2: =IF(E2>0,(F2/E2)*100,0) -> -4.4559585 | J2: =IF(H2>=1234,"High Performer",IF(H2>=295,"Medium","Low Performer")) -> High Performer
A3: FUR-CH-10000454 | B3: =IFERROR(INDEX(Raw_Data!Q:Q,MATCH(Product_Master!A3,Raw_Data!N:N,0)),"NOT FOUND") -> Hon Deluxe Fabric Upholstered Stacking Chairs, Rounded Back | C3: =IFERROR(INDEX(Raw_Data!O:O,MATCH(Product_Master!A3,Raw_Data!N:N,0)),"NOT FOUND") -> Furniture | D3: =IFERROR(INDEX(Raw_Data!P:P,MATCH(Product_Master!A3,Raw_Data!N:N,0)),"NOT FOUND") -> Chairs | E3: =AVERAGEIF(Raw_Data!N:N,Product_Master!A3,Raw_Data!R:R) -> 886.46067 | F3: =AVERAGEIF(Raw_Data!N:N,Product_Master!A3,Raw_Data!U:U) -> 160.62017 | G3: =SUMIF(Raw_Data!N:N,Product_Master!A3,Raw_Data!S:S) -> 51 | H3: =SUMIF(Raw_Data!N:N,Product_Master!A3,Raw_Data!R:R) -> 10637.528 | I3: =IF(E3>0,(F3/E3)*100,0) -> 18.119266 | J3: =IF(H3>=1234,"High Performer",IF(H3>=295,"Medium","Low Performer")) -> High Performer | L3: Max Revenue | M3: =MAX(H:H) -> 61599.824 | N3: High Count | O3: =COUNTIF(J:J,"High Performer") -> 447
A4: OFF-LA-10000240 | B4: =IFERROR(INDEX(Raw_Data!Q:Q,MATCH(Product_Master!A4,Raw_Data!N:N,0)),"NOT FOUND") -> Self-Adhesive Address Labels for Typewriters by Universal | C4: =IFERROR(INDEX(Raw_Data!O:O,MATCH(Product_Master!A4,Raw_Data!N:N,0)),"NOT FOUND") -> Office Supplies | D4: =IFERROR(INDEX(Raw_Data!P:P,MATCH(Product_Master!A4,Raw_Data!N:N,0)),"NOT FOUND") -> Labels | E4: =AVERAGEIF(Raw_Data!N:N,Product_Master!A4,Raw_Data!R:R) -> 21.93 | F4: =AVERAGEIF(Raw_Data!N:N,Product_Master!A4,Raw_Data!U:U) -> 9.2001571 | G4: =SUMIF(Raw_Data!N:N,Product_Master!A4,Raw_Data!S:S) -> 23 | H4: =SUMIF(Raw_Data!N:N,Product_Master!A4,Raw_Data!R:R) -> 153.51 | I4: =IF(E4>0,(F4/E4)*100,0) -> 41.952381 | J4: =IF(H4>=1234,"High Performer",IF(H4>=295,"Medium","Low Performer")) -> Low Performer
A5: FUR-TA-10000577 | B5: =IFERROR(INDEX(Raw_Data!Q:Q,MATCH(Product_Master!A5,Raw_Data!N:N,0)),"NOT FOUND") -> Bretford CR4500 Series Slim Rectangular Table | C5: =IFERROR(INDEX(Raw_Data!O:O,MATCH(Product_Master!A5,Raw_Data!N:N,0)),"NOT FOUND") -> Furniture | D5: =IFERROR(INDEX(Raw_Data!P:P,MATCH(Product_Master!A5,Raw_Data!N:N,0)),"NOT FOUND") -> Tables | E5: =AVERAGEIF(Raw_Data!N:N,Product_Master!A5,Raw_Data!R:R) -> 905.346 | F5: =AVERAGEIF(Raw_Data!N:N,Product_Master!A5,Raw_Data!U:U) -> -66.595163 | G5: =SUMIF(Raw_Data!N:N,Product_Master!A5,Raw_Data!S:S) -> 29 | H5: =SUMIF(Raw_Data!N:N,Product_Master!A5,Raw_Data!R:R) -> 7242.768 | I5: =IF(E5>0,(F5/E5)*100,0) -> -7.3557692 | J5: =IF(H5>=1234,"High Performer",IF(H5>=295,"Medium","Low Performer")) -> High Performer | L5: Min Revenue | M5: =MIN(H:H) -> 1.624 | N5: Medium Count | O5: =COUNTIF(J:J,"Medium") -> 484
A6: OFF-ST-10000760 | B6: =IFERROR(INDEX(Raw_Data!Q:Q,MATCH(Product_Master!A6,Raw_Data!N:N,0)),"NOT FOUND") -> Eldon Fold 'N Roll Cart System | C6: =IFERROR(INDEX(Raw_Data!O:O,MATCH(Product_Master!A6,Raw_Data!N:N,0)),"NOT FOUND") -> Office Supplies | D6: =IFERROR(INDEX(Raw_Data!P:P,MATCH(Product_Master!A6,Raw_Data!N:N,0)),"NOT FOUND") -> Storage | E6: =AVERAGEIF(Raw_Data!N:N,Product_Master!A6,Raw_Data!R:R) -> 60.3936 | F6: =AVERAGEIF(Raw_Data!N:N,Product_Master!A6,Raw_Data!U:U) -> 12.74976 | G6: =SUMIF(Raw_Data!N:N,Product_Master!A6,Raw_Data!S:S) -> 24 | H6: =SUMIF(Raw_Data!N:N,Product_Master!A6,Raw_Data!R:R) -> 301.968 | I6: =IF(E6>0,(F6/E6)*100,0) -> 21.111111 | J6: =IF(H6>=1234,"High Performer",IF(H6>=295,"Medium","Low Performer")) -> Medium
A7: FUR-FU-10001487 | B7: =IFERROR(INDEX(Raw_Data!Q:Q,MATCH(Product_Master!A7,Raw_Data!N:N,0)),"NOT FOUND") -> Eldon Expressions Wood and Plastic Desk Accessories, Cherry Wood | C7: =IFERROR(INDEX(Raw_Data!O:O,MATCH(Product_Master!A7,Raw_Data!N:N,0)),"NOT FOUND") -> Furniture | D7: =IFERROR(INDEX(Raw_Data!P:P,MATCH(Product_Master!A7,Raw_Data!N:N,0)),"NOT FOUND") -> Furnishings | E7: =AVERAGEIF(Raw_Data!N:N,Product_Master!A7,Raw_Data!R:R) -> 32.108 | F7: =AVERAGEIF(Raw_Data!N:N,Product_Master!A7,Raw_Data!U:U) -> 9.31132 | G7: =SUMIF(Raw_Data!N:N,Product_Master!A7,Raw_Data!S:S) -> 23 | H7: =SUMIF(Raw_Data!N:N,Product_Master!A7,Raw_Data!R:R) -> 160.54 | I7: =IF(E7>0,(F7/E7)*100,0) -> 29 | J7: =IF(H7>=1234,"High Performer",IF(H7>=295,"Medium","Low Performer")) -> Low Performer | L7: Average Revenue | M7: =AVERAGE(H:H) -> 1233.7276 | N7: Low Count | O7: =COUNTIF(J:J,"Low Performer") -> 931
A8: OFF-AR-10002833 | B8: =IFERROR(INDEX(Raw_Data!Q:Q,MATCH(Product_Master!A8,Raw_Data!N:N,0)),"NOT FOUND") -> Newell 322 | C8: =IFERROR(INDEX(Raw_Data!O:O,MATCH(Product_Master!A8,Raw_Data!N:N,0)),"NOT FOUND") -> Office Supplies | D8: =IFERROR(INDEX(Raw_Data!P:P,MATCH(Product_Master!A8,Raw_Data!N:N,0)),"NOT FOUND") -> Art | E8: =AVERAGEIF(Raw_Data!N:N,Product_Master!A8,Raw_Data!R:R) -> 5.096 | F8: =AVERAGEIF(Raw_Data!N:N,Product_Master!A8,Raw_Data!U:U) -> 1.1102 | G8: =SUMIF(Raw_Data!N:N,Product_Master!A8,Raw_Data!S:S) -> 18 | H8: =SUMIF(Raw_Data!N:N,Product_Master!A8,Raw_Data!R:R) -> 30.576 | I8: =IF(E8>0,(F8/E8)*100,0) -> 21.785714 | J8: =IF(H8>=1234,"High Performer",IF(H8>=295,"Medium","Low Performer")) -> Low Performer
A9: TEC-PH-10002275 | B9: =IFERROR(INDEX(Raw_Data!Q:Q,MATCH(Product_Master!A9,Raw_Data!N:N,0)),"NOT FOUND") -> Mitel 5320 IP Phone VoIP phone | C9: =IFERROR(INDEX(Raw_Data!O:O,MATCH(Product_Master!A9,Raw_Data!N:N,0)),"NOT FOUND") -> Technology | D9: =IFERROR(INDEX(Raw_Data!P:P,MATCH(Product_Master!A9,Raw_Data!N:N,0)),"NOT FOUND") -> Phones | E9: =AVERAGEIF(Raw_Data!N:N,Product_Master!A9,Raw_Data!R:R) -> 529.172 | F9: =AVERAGEIF(Raw_Data!N:N,Product_Master!A9,Raw_Data!U:U) -> 52.9172 | G9: =SUMIF(Raw_Data!N:N,Product_Master!A9,Raw_Data!S:S) -> 14 | H9: =SUMIF(Raw_Data!N:N,Product_Master!A9,Raw_Data!R:R) -> 2116.688 | I9: =IF(E9>0,(F9/E9)*100,0) -> 10 | J9: =IF(H9>=1234,"High Performer",IF(H9>=295,"Medium","Low Performer")) -> High Performer | L9: Median Revenue | M9: =MEDIAN(H:H) -> 295.452 | N9: Total | O9: =SUM(O3:O8) -> 1862
A10: OFF-BI-10003910 | B10: =IFERROR(INDEX(Raw_Data!Q:Q,MATCH(Product_Master!A10,Raw_Data!N:N,0)),"NOT FOUND") -> DXL Angle-View Binders with Locking Rings by Samsill | C10: =IFERROR(INDEX(Raw_Data!O:O,MATCH(Product_Master!A10,Raw_Data!N:N,0)),"NOT FOUND") -> Office Supplies | D10: =IFERROR(INDEX(Raw_Data!P:P,MATCH(Product_Master!A10,Raw_Data!N:N,0)),"NOT FOUND") -> Binders | E10: =AVERAGEIF(Raw_Data!N:N,Product_Master!A10,Raw_Data!R:R) -> 21.5109 | F10: =AVERAGEIF(Raw_Data!N:N,Product_Master!A10,Raw_Data!U:U) -> 6.66915 | G10: =SUMIF(Raw_Data!N:N,Product_Master!A10,Raw_Data!S:S) -> 35 | H10: =SUMIF(Raw_Data!N:N,Product_Master!A10,Raw_Data!R:R) -> 215.109 | I10: =IF(E10>0,(F10/E10)*100,0) -> 31.003584 | J10: =IF(H10>=1234,"High Performer",IF(H10>=295,"Medium","Low Performer")) -> Low Performer
A11: OFF-AP-10002892 | B11: =IFERROR(INDEX(Raw_Data!Q:Q,MATCH(Product_Master!A11,Raw_Data!N:N,0)),"NOT FOUND") -> Belkin F5C206VTEL 6 Outlet Surge | C11: =IFERROR(INDEX(Raw_Data!O:O,MATCH(Product_Master!A11,Raw_Data!N:N,0)),"NOT FOUND") -> Office Supplies | D11: =IFERROR(INDEX(Raw_Data!P:P,MATCH(Product_Master!A11,Raw_Data!N:N,0)),"NOT FOUND") -> Appliances | E11: =AVERAGEIF(Raw_Data!N:N,Product_Master!A11,Raw_Data!R:R) -> 66.313714 | F11: =AVERAGEIF(Raw_Data!N:N,Product_Master!A11,Raw_Data!U:U) -> 15.757714 | G11: =SUMIF(Raw_Data!N:N,Product_Master!A11,Raw_Data!S:S) -> 22 | H11: =SUMIF(Raw_Data!N:N,Product_Master!A11,Raw_Data!R:R) -> 464.196 | I11: =IF(E11>0,(F11/E11)*100,0) -> 23.762376 | J11: =IF(H11>=1234,"High Performer",IF(H11>=295,"Medium","Low Performer")) -> Medium
A12: FUR-TA-10001539 | B12: =IFERROR(INDEX(Raw_Data!Q:Q,MATCH(Product_Master!A12,Raw_Data!N:N,0)),"NOT FOUND") -> Chromcraft Rectangular Conference Tables | C12: =IFERROR(INDEX(Raw_Data!O:O,MATCH(Product_Master!A12,Raw_Data!N:N,0)),"NOT FOUND") -> Furniture | D12: =IFERROR(INDEX(Raw_Data!P:P,MATCH(Product_Master!A12,Raw_Data!N:N,0)),"NOT FOUND") -> Tables | E12: =AVERAGEIF(Raw_Data!N:N,Product_Master!A12,Raw_Data!R:R) -> 550.297 | F12: =AVERAGEIF(Raw_Data!N:N,Product_Master!A12,Raw_Data!U:U) -> -50.027 | G12: =SUMIF(Raw_Data!N:N,Product_Master!A12,Raw_Data!S:S) -> 30 | H12: =SUMIF(Raw_Data!N:N,Product_Master!A12,Raw_Data!R:R) -> 4952.673 | I12: =IF(E12>0,(F12/E12)*100,0) -> -9.0909091 | J12: =IF(H12>=1234,"High Performer",IF(H12>=295,"Medium","Low Performer")) -> High Performer
A13: TEC-PH-10002033 | B13: =IFERROR(INDEX(Raw_Data!Q:Q,MATCH(Product_Master!A13,Raw_Data!N:N,0)),"NOT FOUND") -> Konftel 250 Conference phone - Charcoal black | C13: =IFERROR(INDEX(Raw_Data!O:O,MATCH(Product_Master!A13,Raw_Data!N:N,0)),"NOT FOUND") -> Technology | D13: =IFERROR(INDEX(Raw_Data!P:P,MATCH(Product_Master!A13,Raw_Data!N:N,0)),"NOT FOUND") -> Phones | E13: =AVERAGEIF(Raw_Data!N:N,Product_Master!A13,Raw_Data!R:R) -> 555.399 | F13: =AVERAGEIF(Raw_Data!N:N,Product_Master!A13,Raw_Data!U:U) -> 81.1737 | G13: =SUMIF(Raw_Data!N:N,Product_Master!A13,Raw_Data!S:S) -> 9 | H13: =SUMIF(Raw_Data!N:N,Product_Master!A13,Raw_Data!R:R) -> 2221.596 | I13: =IF(E13>0,(F13/E13)*100,0) -> 14.615385 | J13: =IF(H13>=1234,"High Performer",IF(H13>=295,"Medium","Low Performer")) -> High Performer
A14: OFF-PA-10002365 | B14: =IFERROR(INDEX(Raw_Data!Q:Q,MATCH(Product_Master!A14,Raw_Data!N:N,0)),"NOT FOUND") -> Xerox 1967 | C14: =IFERROR(INDEX(Raw_Data!O:O,MATCH(Product_Master!A14,Raw_Data!N:N,0)),"NOT FOUND") -> Office Supplies | D14: =IFERROR(INDEX(Raw_Data!P:P,MATCH(Product_Master!A14,Raw_Data!N:N,0)),"NOT FOUND") -> Paper | E14: =AVERAGEIF(Raw_Data!N:N,Product_Master!A14,Raw_Data!R:R) -> 17.8848 | F14: =AVERAGEIF(Raw_Data!N:N,Product_Master!A14,Raw_Data!U:U) -> 7.776 | G14: =SUMIF(Raw_Data!N:N,Product_Master!A14,Raw_Data!S:S) -> 15 | H14: =SUMIF(Raw_Data!N:N,Product_Master!A14,Raw_Data!R:R) -> 89.424 | I14: =IF(E14>0,(F14/E14)*100,0) -> 43.478261 | J14: =IF(H14>=1234,"High Performer",IF(H14>=295,"Medium","Low Performer")) -> Low Performer
A15: OFF-BI-10003656 | B15: =IFERROR(INDEX(Raw_Data!Q:Q,MATCH(Product_Master!A15,Raw_Data!N:N,0)),"NOT FOUND") -> Fellowes PB200 Plastic Comb Binding Machine | C15: =IFERROR(INDEX(Raw_Data!O:O,MATCH(Product_Master!A15,Raw_Data!N:N,0)),"NOT FOUND") -> Office Supplies | D15: =IFERROR(INDEX(Raw_Data!P:P,MATCH(Product_Master!A15,Raw_Data!N:N,0)),"NOT FOUND") -> Binders | E15: =AVERAGEIF(Raw_Data!N:N,Product_Master!A15,Raw_Data!R:R) -> 464.63933 | F15: =AVERAGEIF(Raw_Data!N:N,Product_Master!A15,Raw_Data!U:U) -> 77.062133 | G15: =SUMIF(Raw_Data!N:N,Product_Master!A15,Raw_Data!S:S) -> 38 | H15: =SUMIF(Raw_Data!N:N,Product_Master!A15,Raw_Data!R:R) -> 4181.754 | I15: =IF(E15>0,(F15/E15)*100,0) -> 16.585366 | J15: =IF(H15>=1234,"High Performer",IF(H15>=295,"Medium","Low Performer")) -> High Performer
A16: OFF-AP-10002311 | B16: =IFERROR(INDEX(Raw_Data!Q:Q,MATCH(Product_Master!A16,Raw_Data!N:N,0)),"NOT FOUND") -> Holmes Replacement Filter for HEPA Air Cleaner, Very Large Room, HEPA Filter | C16: =IFERROR(INDEX(Raw_Data!O:O,MATCH(Product_Master!A16,Raw_Data!N:N,0)),"NOT FOUND") -> Office Supplies | D16: =IFERROR(INDEX(Raw_Data!P:P,MATCH(Product_Master!A16,Raw_Data!N:N,0)),"NOT FOUND") -> Appliances | E16: =AVERAGEIF(Raw_Data!N:N,Product_Master!A16,Raw_Data!R:R) -> 138.3081 | F16: =AVERAGEIF(Raw_Data!N:N,Product_Master!A16,Raw_Data!U:U) -> 38.12074 | G16: =SUMIF(Raw_Data!N:N,Product_Master!A16,Raw_Data!S:S) -> 26 | H16: =SUMIF(Raw_Data!N:N,Product_Master!A16,Raw_Data!R:R) -> 1383.081 | I16: =IF(E16>0,(F16/E16)*100,0) -> 27.562189 | J16: =IF(H16>=1234,"High Performer",IF(H16>=295,"Medium","Low Performer")) -> High Performer
A17: OFF-BI-10000756 | B17: =IFERROR(INDEX(Raw_Data!Q:Q,MATCH(Product_Master!A17,Raw_Data!N:N,0)),"NOT FOUND") -> Storex DuraTech Recycled Plastic Frosted Binders | C17: =IFERROR(INDEX(Raw_Data!O:O,MATCH(Product_Master!A17,Raw_Data!N:N,0)),"NOT FOUND") -> Office Supplies | D17: =IFERROR(INDEX(Raw_Data!P:P,MATCH(Product_Master!A17,Raw_Data!N:N,0)),"NOT FOUND") -> Binders | E17: =AVERAGEIF(Raw_Data!N:N,Product_Master!A17,Raw_Data!R:R) -> 11.766 | F17: =AVERAGEIF(Raw_Data!N:N,Product_Master!A17,Raw_Data!U:U) -> 1.431 | G17: =SUMIF(Raw_Data!N:N,Product_Master!A17,Raw_Data!S:S) -> 39 | H17: =SUMIF(Raw_Data!N:N,Product_Master!A17,Raw_Data!R:R) -> 94.128 | I17: =IF(E17>0,(F17/E17)*100,0) -> 12.162162 | J17: =IF(H17>=1234,"High Performer",IF(H17>=295,"Medium","Low Performer")) -> Low Performer
A18: OFF-ST-10004186 | B18: =IFERROR(INDEX(Raw_Data!Q:Q,MATCH(Product_Master!A18,Raw_Data!N:N,0)),"NOT FOUND") -> Stur-D-Stor Shelving, Vertical 5-Shelf: 72"H x 36"W x 18 1/2"D | C18: =IFERROR(INDEX(Raw_Data!O:O,MATCH(Product_Master!A18,Raw_Data!N:N,0)),"NOT FOUND") -> Office Supplies | D18: =IFERROR(INDEX(Raw_Data!P:P,MATCH(Product_Master!A18,Raw_Data!N:N,0)),"NOT FOUND") -> Storage | E18: =AVERAGEIF(Raw_Data!N:N,Product_Master!A18,Raw_Data!R:R) -> 510.508 | F18: =AVERAGEIF(Raw_Data!N:N,Product_Master!A18,Raw_Data!U:U) -> 10.21016 | G18: =SUMIF(Raw_Data!N:N,Product_Master!A18,Raw_Data!S:S) -> 23 | H18: =SUMIF(Raw_Data!N:N,Product_Master!A18,Raw_Data!R:R) -> 2552.54 | I18: =IF(E18>0,(F18/E18)*100,0) -> 2 | J18: =IF(H18>=1234,"High Performer",IF(H18>=295,"Medium","Low Performer")) -> High Performer
A19: OFF-ST-10000107 | B19: =IFERROR(INDEX(Raw_Data!Q:Q,MATCH(Product_Master!A19,Raw_Data!N:N,0)),"NOT FOUND") -> Fellowes Super Stor/Drawer | C19: =IFERROR(INDEX(Raw_Data!O:O,MATCH(Product_Master!A19,Raw_Data!N:N,0)),"NOT FOUND") -> Office Supplies | D19: =IFERROR(INDEX(Raw_Data!P:P,MATCH(Product_Master!A19,Raw_Data!N:N,0)),"NOT FOUND") -> Storage | E19: =AVERAGEIF(Raw_Data!N:N,Product_Master!A19,Raw_Data!R:R) -> 119.325 | F19: =AVERAGEIF(Raw_Data!N:N,Product_Master!A19,Raw_Data!U:U) -> 16.9275 | G19: =SUMIF(Raw_Data!N:N,Product_Master!A19,Raw_Data!S:S) -> 18 | H19: =SUMIF(Raw_Data!N:N,Product_Master!A19,Raw_Data!R:R) -> 477.3 | I19: =IF(E19>0,(F19/E19)*100,0) -> 14.186047 | J19: =IF(H19>=1234,"High Performer",IF(H19>=295,"Medium","Low Performer")) -> Medium
A20: OFF-AR-10003056 | B20: =IFERROR(INDEX(Raw_Data!Q:Q,MATCH(Product_Master!A20,Raw_Data!N:N,0)),"NOT FOUND") -> Newell 341 | C20: =IFERROR(INDEX(Raw_Data!O:O,MATCH(Product_Master!A20,Raw_Data!N:N,0)),"NOT FOUND") -> Office Supplies | D20: =IFERROR(INDEX(Raw_Data!P:P,MATCH(Product_Master!A20,Raw_Data!N:N,0)),"NOT FOUND") -> Art | E20: =AVERAGEIF(Raw_Data!N:N,Product_Master!A20,Raw_Data!R:R) -> 13.818286 | F20: =AVERAGEIF(Raw_Data!N:N,Product_Master!A20,Raw_Data!U:U) -> 3.8336571 | G20: =SUMIF(Raw_Data!N:N,Product_Master!A20,Raw_Data!S:S) -> 23 | H20: =SUMIF(Raw_Data!N:N,Product_Master!A20,Raw_Data!R:R) -> 96.728 | I20: =IF(E20>0,(F20/E20)*100,0) -> 27.743363 | J20: =IF(H20>=1234,"High Performer",IF(H20>=295,"Medium","Low Performer")) -> Low Performer
A21: TEC-PH-10001949 | B21: =IFERROR(INDEX(Raw_Data!Q:Q,MATCH(Product_Master!A21,Raw_Data!N:N,0)),"NOT FOUND") -> Cisco SPA 501G IP Phone | C21: =IFERROR(INDEX(Raw_Data!O:O,MATCH(Product_Master!A21,Raw_Data!N:N,0)),"NOT FOUND") -> Technology | D21: =IFERROR(INDEX(Raw_Data!P:P,MATCH(Product_Master!A21,Raw_Data!N:N,0)),"NOT FOUND") -> Phones | E21: =AVERAGEIF(Raw_Data!N:N,Product_Master!A21,Raw_Data!R:R) -> 213.48 | F21: =AVERAGEIF(Raw_Data!N:N,Product_Master!A21,Raw_Data!U:U) -> 16.011 | G21: =SUMIF(Raw_Data!N:N,Product_Master!A21,Raw_Data!S:S) -> 3 | H21: =SUMIF(Raw_Data!N:N,Product_Master!A21,Raw_Data!R:R) -> 213.48 | I21: =IF(E21>0,(F21/E21)*100,0) -> 7.5 | J21: =IF(H21>=1234,"High Performer",IF(H21>=295,"Medium","Low Performer")) -> Low Performer
... A1863: OFF-ST-10001627 | B1863: =IFERROR(INDEX(Raw_Data!Q:Q,MATCH(Product_Master!A1863,Raw_Data!N:N,0)),"NOT FOUND") -> Eldon Jumbo ProFile Portable File Boxes Graphite/Black | C1863: =IFERROR(INDEX(Raw_Data!O:O,MATCH(Product_Master!A1863,Raw_Data!N:N,0)),"NOT FOUND") -> Office Supplies | D1863: =IFERROR(INDEX(Raw_Data!P:P,MATCH(Product_Master!A1863,Raw_Data!N:N,0)),"NOT FOUND") -> Storage | E1863: =AVERAGEIF(Raw_Data!N:N,Product_Master!A1863,Raw_Data!R:R) -> 36.744 | F1863: =AVERAGEIF(Raw_Data!N:N,Product_Master!A1863,Raw_Data!U:U) -> 3.6744 | G1863: =SUMIF(Raw_Data!N:N,Product_Master!A1863,Raw_Data!S:S) -> 3 | H1863: =SUMIF(Raw_Data!N:N,Product_Master!A1863,Raw_Data!R:R) -> 36.744 | I1863: =IF(E1863>0,(F1863/E1863)*100,0) -> 10 | J1863: =IF(H1863>=1234,"High Performer",IF(H1863>=295,"Medium","Low Performer")) -> Low Performer

Sheet Pivot_Category
A3: Row Labels | B3: Sum of Sales
A4: Furniture | B4: 741999.8
A5: Office Supplies | B5: 719047.03
A6: Technology | B6: 836154.03
A7: Grand Total | B7: 2297200.9

Sheet Pivot_Region
A3: Row Labels | B3: Sum of Sales | C3: Orders | D3: Sum of Profit
A4: Central | B4: 501239.89 | C4: 2323 | D4: 39706.362
A5: East | B5: 678781.24 | C5: 2848 | D5: 91522.78
A6: South | B6: 391721.91 | C6: 1620 | D6: 46749.43
A7: West | B7: 725457.82 | C7: 3203 | D7: 108418.45
A8: Grand Total | B8: 2297200.9 | C8: 9994 | D8: 286397.02

Sheet Pivot_Trend
A3: Row Labels | B3: Sum of Sales | C3: Sum of Profit
A4: 2014 | B4: 484247.5 | C4: 49543.974
A5: 2015 | B5: 470532.51 | C5: 61618.604
A6: 2016 | B6: 609205.6 | C6: 81795.174
A7: 2017 | B7: 733215.26 | C7: 93439.27
A8: Grand Total | B8: 2297200.9 | C8: 286397.02

Sheet Pivot_Products
A3: Row Labels | B3: Sum of Sales
A4: Accessories | B4: 167380.32
A5: Appliances | B5: 107532.16
A6: Binders | B6: 203412.73
A7: Bookcases | B7: 114880
A8: Chairs | B8: 328449.1
A9: Copiers | B9: 149528.03
A10: Machines | B10: 189238.63
A11: Phones | B11: 330007.05
A12: Storage | B12: 223843.61
A13: Tables | B13: 206965.53
A14: Grand Total | B14: 2021237.2

Sheet Pivot_Segments
A3: Row Labels | B3: Sum of Sales | C3: Sum of Profit
A4: Consumer | B4: 1161401.3 | C4: 134119.21
A5: Corporate | B5: 706146.37 | C5: 91979.134
A6: Home Office | B6: 429653.15 | C6: 60298.679
A7: Grand Total | B7: 2297200.9 | C7: 286397.02

Sheet Raw_Data
A1: Row ID | B1: Order ID | C1: Order Date | D1: Ship Date | E1: Ship Mode | F1: Customer ID | G1: Customer Name | H1: Segment | I1: Country | J1: City | K1: State | L1: Postal Code | M1: Region | N1: Product ID | O1: Category | P1: Sub-Category | Q1: Product Name | R1: Sales | S1: Quantity | T1: Discount | U1: Profit | V1: Month | W1: Quarter | X1: Year | Y1: Month Name | Z1: Year-Month
A2: 1 | B2: CA-2016-152156 | C2: 42682 | D2: 42685 | E2: Second Class | F2: CG-12520 | G2: Claire Gute | H2: Consumer | I2: United States | J2: Henderson | K2: Kentucky | L2: 42420 | M2: South | N2: FUR-BO-10001798 | O2: Furniture | P2: Bookcases | Q2: Bush Somerset Collection Bookcase | R2: 261.96 | S2: 2 | T2: 0 | U2: 41.9136 | V2: =MONTH(C2) -> 11 | W2: =ROUNDUP(MONTH(C2)/3,0) -> 4 | X2: =YEAR(C2) -> 2016 | Y2: =TEXT(C2,"MMM") -> Nov | Z2: =TEXT(C2,"YYYY-MM") -> 2016-11
A3: 2 | B3: CA-2016-152156 | C3: 42682 | D3: 42685 | E3: Second Class | F3: CG-12520 | G3: Claire Gute | H3: Consumer | I3: United States | J3: Henderson | K3: Kentucky | L3: 42420 | M3: South | N3: FUR-CH-10000454 | O3: Furniture | P3: Chairs | Q3: Hon Deluxe Fabric Upholstered Stacking Chairs, Rounded Back | R3: 731.94 | S3: 3 | T3: 0 | U3: 219.582 | V3: =MONTH(C3) -> 11 | W3: =ROUNDUP(MONTH(C3)/3,0) -> 4 | X3: =YEAR(C3) -> 2016 | Y3: =TEXT(C3,"MMM") -> Nov | Z3: =TEXT(C3,"YYYY-MM") -> 2016-11
A4: 3 | B4: CA-2016-138688 | C4: 42533 | D4: 42537 | E4: Second Class | F4: DV-13045 | G4: Darrin Van Huff | H4: Corporate | I4: United States | J4: Los Angeles | K4: California | L4: 90036 | M4: West | N4: OFF-LA-10000240 | O4: Office Supplies | P4: Labels | Q4: Self-Adhesive Address Labels for Typewriters by Universal | R4: 14.62 | S4: 2 | T4: 0 | U4: 6.8714 | V4: =MONTH(C4) -> 6 | W4: =ROUNDUP(MONTH(C4)/3,0) -> 2 | X4: =YEAR(C4) -> 2016 | Y4: =TEXT(C4,"MMM") -> Jun | Z4: =TEXT(C4,"YYYY-MM") -> 2016-06
A5: 4 | B5: US-2015-108966 | C5: 42288 | D5: 42295 | E5: Standard Class | F5: SO-20335 | G5: Sean O'Donnell | H5: Consumer | I5: United States | J5: Fort Lauderdale | K5: Florida | L5: 33311 | M5: South | N5: FUR-TA-10000577 | O5: Furniture | P5: Tables | Q5: Bretford CR4500 Series Slim Rectangular Table | R5: 957.5775 | S5: 5 | T5: 0.45 | U5: -383.031 | V5: =MONTH(C5) -> 10 | W5: =ROUNDUP(MONTH(C5)/3,0) -> 4 | X5: =YEAR(C5) -> 2015 | Y5: =TEXT(C5,"MMM") -> Oct | Z5: =TEXT(C5,"YYYY-MM") -> 2015-10
A6: 5 | B6: US-2015-108966 | C6: 42288 | D6: 42295 | E6: Standard Class | F6: SO-20335 | G6: Sean O'Donnell | H6: Consumer | I6: United States | J6: Fort Lauderdale | K6: Florida | L6: 33311 | M6: South | N6: OFF-ST-10000760 | O6: Office Supplies | P6: Storage | Q6: Eldon Fold 'N Roll Cart System | R6: 22.368 | S6: 2 | T6: 0.2 | U6: 2.5164 | V6: =MONTH(C6) -> 10 | W6: =ROUNDUP(MONTH(C6)/3,0) -> 4 | X6: =YEAR(C6) -> 2015 | Y6: =TEXT(C6,"MMM") -> Oct | Z6: =TEXT(C6,"YYYY-MM") -> 2015-10
A7: 6 | B7: CA-2014-115812 | C7: 41799 | D7: 41804 | E7: Standard Class | F7: BH-11710 | G7: Brosina Hoffman | H7: Consumer | I7: United States | J7: Los Angeles | K7: California | L7: 90032 | M7: West | N7: FUR-FU-10001487 | O7: Furniture | P7: Furnishings | Q7: Eldon Expressions Wood and Plastic Desk Accessories, Cherry Wood | R7: 48.86 | S7: 7 | T7: 0 | U7: 14.1694 | V7: =MONTH(C7) -> 6 | W7: =ROUNDUP(MONTH(C7)/3,0) -> 2 | X7: =YEAR(C7) -> 2014 | Y7: =TEXT(C7,"MMM") -> Jun | Z7: =TEXT(C7,"YYYY-MM") -> 2014-06
A8: 7 | B8: CA-2014-115812 | C8: 41799 | D8: 41804 | E8: Standard Class | F8: BH-11710 | G8: Brosina Hoffman | H8: Consumer | I8: United States | J8: Los Angeles | K8: California | L8: 90032 | M8: West | N8: OFF-AR-10002833 | O8: Office Supplies | P8: Art | Q8: Newell 322 | R8: 7.28 | S8: 4 | T8: 0 | U8: 1.9656 | V8: =MONTH(C8) -> 6 | W8: =ROUNDUP(MONTH(C8)/3,0) -> 2 | X8: =YEAR(C8) -> 2014 | Y8: =TEXT(C8,"MMM") -> Jun | Z8: =TEXT(C8,"YYYY-MM") -> 2014-06
A9: 8 | B9: CA-2014-115812 | C9: 41799 | D9: 41804 | E9: Standard Class | F9: BH-11710 | G9: Brosina Hoffman | H9: Consumer | I9: United States | J9: Los Angeles | K9: California | L9: 90032 | M9: West | N9: TEC-PH-10002275 | O9: Technology | P9: Phones | Q9: Mitel 5320 IP Phone VoIP phone | R9: 907.152 | S9: 6 | T9: 0.2 | U9: 90.7152 | V9: =MONTH(C9) -> 6 | W9: =ROUNDUP(MONTH(C9)/3,0) -> 2 | X9: =YEAR(C9) -> 2014 | Y9: =TEXT(C9,"MMM") -> Jun | Z9: =TEXT(C9,"YYYY-MM") -> 2014-06
A10: 9 | B10: CA-2014-115812 | C10: 41799 | D10: 41804 | E10: Standard Class | F10: BH-11710 | G10: Brosina Hoffman | H10: Consumer | I10: United States | J10: Los Angeles | K10: California | L10: 90032 | M10: West | N10: OFF-BI-10003910 | O10: Office Supplies | P10: Binders | Q10: DXL Angle-View Binders with Locking Rings by Samsill | R10: 18.504 | S10: 3 | T10: 0.2 | U10: 5.7825 | V10: =MONTH(C10) -> 6 | W10: =ROUNDUP(MONTH(C10)/3,0) -> 2 | X10: =YEAR(C10) -> 2014 | Y10: =TEXT(C10,"MMM") -> Jun | Z10: =TEXT(C10,"YYYY-MM") -> 2014-06
A11: 10 | B11: CA-2014-115812 | C11: 41799 | D11: 41804 | E11: Standard Class | F11: BH-11710 | G11: Brosina Hoffman | H11: Consumer | I11: United States | J11: Los Angeles | K11: California | L11: 90032 | M11: West | N11: OFF-AP-10002892 | O11: Office Supplies | P11: Appliances | Q11: Belkin F5C206VTEL 6 Outlet Surge | R11: 114.9 | S11: 5 | T11: 0 | U11: 34.47 | V11: =MONTH(C11) -> 6 | W11: =ROUNDUP(MONTH(C11)/3,0) -> 2 | X11: =YEAR(C11) -> 2014 | Y11: =TEXT(C11,"MMM") -> Jun | Z11: =TEXT(C11,"YYYY-MM") -> 2014-06
A12: 11 | B12: CA-2014-115812 | C12: 41799 | D12: 41804 | E12: Standard Class | F12: BH-11710 | G12: Brosina Hoffman | H12: Consumer | I12: United States | J12: Los Angeles | K12: California | L12: 90032 | M12: West | N12: FUR-TA-10001539 | O12: Furniture | P12: Tables | Q12: Chromcraft Rectangular Conference Tables | R12: 1706.184 | S12: 9 | T12: 0.2 | U12: 85.3092 | V12: =MONTH(C12) -> 6 | W12: =ROUNDUP(MONTH(C12)/3,0) -> 2 | X12: =YEAR(C12) -> 2014 | Y12: =TEXT(C12,"MMM") -> Jun | Z12: =TEXT(C12,"YYYY-MM") -> 2014-06
A13: 12 | B13: CA-2014-115812 | C13: 41799 | D13: 41804 | E13: Standard Class | F13: BH-11710 | G13: Brosina Hoffman | H13: Consumer | I13: United States | J13: Los Angeles | K13: California | L13: 90032 | M13: West | N13: TEC-PH-10002033 | O13: Technology | P13: Phones | Q13: Konftel 250 Conference phone - Charcoal black | R13: 911.424 | S13: 4 | T13: 0.2 | U13: 68.3568 | V13: =MONTH(C13) -> 6 | W13: =ROUNDUP(MONTH(C13)/3,0) -> 2 | X13: =YEAR(C13) -> 2014 | Y13: =TEXT(C13,"MMM") -> Jun | Z13: =TEXT(C13,"YYYY-MM") -> 2014-06
... A9995: 9994 | B9995: CA-2017-119914 | C9995: 42859 | D9995: 42864 | E9995: Second Class | F9995: CC-12220 | G9995: Chris Cortes | H9995: Consumer | I9995: United States | J9995: Westminster | K9995: California | L9995: 92683 | M9995: West | N9995: OFF-AP-10002684 | O9995: Office Supplies | P9995: Appliances | Q9995: Acco 7-Outlet Masterpiece Power Center, Wihtout Fax/Phone Line Protection | R9995: 243.16 | S9995: 2 | T9995: 0 | U9995: 72.948 | V9995: =MONTH(C9995) -> 5 | W9995: =ROUNDUP(MONTH(C9995)/3,0) -> 2 | X9995: =YEAR(C9995) -> 2017 | Y9995: =TEXT(C9995,"MMM") -> May | Z9995: =TEXT(C9995,"YYYY-MM") -> 2017-05
